Workbook

Sheet 使い方
A1: G-SELECT
A2: SELECT ITEM 追加用スプレッドシート
A4: このシートの目的
B5: SELECT ITEM（product_sample.html）に掲載中の全アイテムのデータを反映し、新しいアイテムを追加するための入力フォームとしてまとめたものです。
B6: 新しいアイテムを追加したい場合は、各シートの「▼ここから新規追加▼」の下にある空いている行に入力し、このファイルをClaudeに渡して「このスプレッドシートの内容でSELECT ITEMにアイテムを追加して」と依頼してください。Webサイトへの反映はClaudeが行います。
B7: 既存アイテムの内容を修正したい場合は、該当行を直接書き換えて、修正した旨を添えてClaudeに渡してください。
A9: ★重要：新しい行は必ず「新規追加」欄に入力してください
B10: 商品IDの自動採番と、カタログリンクシートの商品ID自動連携は「行の位置」を基準に数式で動いています。
B11: 既存アイテムの行の間に新しい行を挿入すると、自動採番やリンクの対応がずれてしまいます。新しいアイテムは必ず「▼ここから新規追加▼」より下の、あらかじめ用意した空欄行に入力してください。
B12: 空欄行が足りなくなった場合は、行を挿入せずClaudeに「新規追加欄を増やして」と依頼してください。
A14: シート構成（3枚＋設定シート）
B15: ①「商品マスタ」…アイテム1件につき1行。商品ID・カテゴリー・メーカー・商品名・説明文・画像などの基本情報。商品IDは掲載カテゴリーを選ぶと自動で採番されます（例：床材→floor-01, floor-02…）。
B16: ②「カラー展開」…カラー（色見本）がある商品のみ、色の数だけ行があります（1色〜18色まで商品により様々です）。商品マスタの商品IDをプルダウンで選んで紐づけます。
B17: ③「カタログリンク」…メーカーカタログ等へのリンクボタン（最大2件）。商品マスタと同じ並び順・同じ行数になっており、商品IDは自動で商品マスタから反映されます（入力不要）。
B18: 「設定」シートは商品ID自動採番のための内部データです。編集しないでください（通常は非表示になっています）。
A20: 商品ID（自動採番）
B21: 商品マスタの「商品ID」列は入力不要です。「掲載カテゴリー」を選択すると、「カテゴリーの英語コード-連番」の形で自動的に採番されます（例：floor-01, water-03）。
B22: カラー展開シートでは、対応する商品ID（自動採番された値）をプルダウンから選んで入力してください。
B23: カタログリンクシートの商品IDは商品マスタと行位置で自動連携されるため、入力不要です。
A25: プルダウン（入力規則）について
B26: 「掲載カテゴリー」「メーカー名」「商品分類」「ボタン表示文言」は、現在Webサイトに実際に掲載されている値をプルダウンの選択肢にしています。
B27: リストに無い新しいメーカー・分類・カテゴリーが必要な場合は、プルダウンを使わず直接セルに入力していただいて構いません（入力自体はブロックされません）。
A29: 画像について
B30: 画像ファイルそのものはこのシートには貼らず、担当者からClaudeへ別途データ（jpg/png）を渡してください。
B31: 新規アイテムの「画像ファイル名」列には、渡すファイルに付ける名前（半角英数、例：newitem.jpg）だけを入力します。
A33: カラーコード（HEX）について
B34: カラー名だけで構いません。HEXコード（#rrggbb）が分かる場合は入力すると、より正確な色見本になります。分からない場合は空欄でOKです。
A36: 2026-09-03時点でのWebサイトのアイテム掲載順（このシートのカテゴリープルダウンも同じ順番です）
B37: 1. 床材
B38: 2. 壁材（現在サイト上は準備中）
B39: 3. 植栽
B40: 4. デッキ
B41: 5. 照明
B42: 6. 表札
B43: 7. ポスト
B44: 8. 機能門柱
B45: 9. 人工芝・砂利
B46: 10. 立水栓
B47: 11. 木製エクステリア（Gストック）
B48: 12. デザインフェンス（現在サイト上は準備中）
...

Sheet 商品マスタ
A1: 商品ID（自動） | B1: 掲載カテゴリー* | C1: メーカー名 | D1: 商品分類（メーカー内の種別） | E1: 商品名* | F1: 商品説明文* | G1: 画像ファイル名* | H1: 画像alt文言（SEO用）* | I1: 特設サイトリンクURL | J1: 備考
A2: =IF($B2="","",VLOOKUP($B2,設定!$A$2:$B$13,2,FALSE)&"-"&TEXT(COUNTIF($B$2:$B2,$B2),"00")) | B2: 床材 | C2: 東洋工業 | D2: インターロッキング | E2: エクレル | F2: 土や樹木に調和する色調に、自然に馴染む色ムラを表現。和洋問わず幅広くコーディネート。 | G2: ecrele.jpg | H2: インターロッキング 東洋工業 エクレル
A3: =IF($B3="","",VLOOKUP($B3,設定!$A$2:$B$13,2,FALSE)&"-"&TEXT(COUNTIF($B$2:$B3,$B3),"00")) | B3: 床材 | C3: 東洋工業 | D3: インターロッキング | E3: ポルドブリック | F3: イタリア斑岩のような落ち着いた色調と質感で、気品漂う空間を演出。 | G3: pordobrick.jpg | H3: インターロッキング 東洋工業 ポルドブリック
A4: =IF($B4="","",VLOOKUP($B4,設定!$A$2:$B$13,2,FALSE)&"-"&TEXT(COUNTIF($B$2:$B4,$B4),"00")) | B4: 床材 | C4: 東洋工業 | D4: インターロッキング | E4: ニュートペイブ | F4: ラフに仕上げた表面やエッジが、時と共にこなれた空間に。 | G4: neutepave.jpg | H4: インターロッキング 東洋工業 ニュートペイブ
A5: =IF($B5="","",VLOOKUP($B5,設定!$A$2:$B$13,2,FALSE)&"-"&TEXT(COUNTIF($B$2:$B5,$B5),"00")) | B5: 床材 | C5: 東洋工業 | D5: インターロッキング | E5: カルムストーン | F5: 天然石の深みある色合いを再現し、独自のRD加工によるナチュラルな質感が特徴。乱形ランダム模様で美しい空間に。 | G5: calmestone.jpg | H5: インターロッキング 東洋工業 カルムストーン
A6: =IF($B6="","",VLOOKUP($B6,設定!$A$2:$B$13,2,FALSE)&"-"&TEXT(COUNTIF($B$2:$B6,$B6),"00")) | B6: 床材 | C6: 東洋工業 | D6: 平板 | E6: ヴィンテージウッドペイブ | F6: 使い古された天然木のような質感が、ぬくもりのある空間を演出。 | G6: vintagewoodpave.jpg | H6: 平板 東洋工業 ヴィンテージウッドペイブ
A7: =IF($B7="","",VLOOKUP($B7,設定!$A$2:$B$13,2,FALSE)&"-"&TEXT(COUNTIF($B$2:$B7,$B7),"00")) | B7: 床材 | C7: 東洋工業 | D7: 平板 | E7: スギーペイブ | F7: 杉板型枠のコンクリート打ち放しの素材感は、スタイリッシュに自然に馴染む。 | G7: sugiepave.jpg | H7: 平板 東洋工業 スギーペイブ
A8: =IF($B8="","",VLOOKUP($B8,設定!$A$2:$B$13,2,FALSE)&"-"&TEXT(COUNTIF($B$2:$B8,$B8),"00")) | B8: 床材 | C8: メイクランド | D8: レンガ | E8: ステラ | F8: 積み敷き兼用タイプで、オーソドックスな定番カラーが落ち着いた印象のレンガです。 | G8: stella.jpg | H8: レンガ メイクランド ステラ
A9: =IF($B9="","",VLOOKUP($B9,設定!$A$2:$B$13,2,FALSE)&"-"&TEXT(COUNTIF($B$2:$B9,$B9),"00")) | B9: 床材 | C9: シンセイ福岡 | D9: レンガ | E9: ソイルレンガ | F9: 土のぬくもりが漂う表面に、独特の焼きムラを加えた味わい深いレンガ。高温焼成により美しさ長持ち。 | G9: soilbrick.jpg | H9: レンガ エクシスランド ソイルレンガ
A10: =IF($B10="","",VLOOKUP($B10,設定!$A$2:$B$13,2,FALSE)&"-"&TEXT(COUNTIF($B$2:$B10,$B10),"00")) | B10: 床材 | C10: メイクランド | D10: レンガ | E10: 風シリーズ | F10: リーズナブルな国産のレンガで、色調に変化のある風シリーズは人気の商品です。 | G10: kaze.jpg | H10: レンガ メイクランド 風
A11: =IF($B11="","",VLOOKUP($B11,設定!$A$2:$B$13,2,FALSE)&"-"&TEXT(COUNTIF($B$2:$B11,$B11),"00")) | B11: 床材 | C11: シンセイ福岡 | D11: レンガ | E11: シンセイブリック | F11: 高品質と機能性を重視したスタンダード積みレンガ。主張し過ぎない柔らかい表情と自然な色ムラが特徴。 | G11: sinseibrick.jpg | H11: レンガ エクシスランド シンセイブリック
A12: =IF($B12="","",VLOOKUP($B12,設定!$A$2:$B$13,2,FALSE)&"-"&TEXT(COUNTIF($B$2:$B12,$B12),"00")) | B12: 床材 | C12: 東洋工業 | D12: レンガ | E12: シャルドブリックペイブ | F12: ヴィンテージレンガの質感と色調を再現。表面もこだわりのある凹凸で魅力的な古さを想わせる風合い。 | G12: chaldbrick.jpg | H12: レンガ 東洋工業 シャルドブリックペイブ
A13: =IF($B13="","",VLOOKUP($B13,設定!$A$2:$B$13,2,FALSE)&"-"&TEXT(COUNTIF($B$2:$B13,$B13),"00")) | B13: 床材 | C13: メイクランド/EXISLAND | D13: ピンコロ | E13: ブイグラニット/ピンコロ | F13: 形状が安定し施工性に優れ、豊富なカラーとサイズで活躍。 | G13: vgranite.jpg | H13: エクシスランド ビンコロ メイクランド ブイグラニット
... A27: =IF($B27="","",VLOOKUP($B27,設定!$A$2:$B$13,2,FALSE)&"-"&TEXT(COUNTIF($B$2:$B27,$B27),"00")) | B27: 壁材 | C27: アイカ工業 | D27: 塗り壁材 | E27: ジョリパット | F27: 左官仕上げで意匠性を高める塗り壁材。カラーは180色以上と無数にありますが、その中からグランド工房イチオシの推奨10色（白系・黒系・茶系）をセレクトしました。建物の色味に合わせて選ぶと統一感のある美しい空間になります。 | G27: jolipate.jpg | H27: 壁材 アイカ工業 ジョリパット
A28: =IF($B28="","",VLOOKUP($B28,設定!$A$2:$B$13,2,FALSE)&"-"&TEXT(COUNTIF($B$2:$B28,$B28),"00")) | B28: 植栽 | E28: 落葉高木 | F28: 日本の山地に自生する落葉樹。秋の紅葉が美しく、庭木や公園樹として人気。 | G28: yamamomiji.jpg | H28: 植栽 ヤマモミジ
A29: =IF($B29="","",VLOOKUP($B29,設定!$A$2:$B$13,2,FALSE)&"-"&TEXT(COUNTIF($B$2:$B29,$B29),"00")) | B29: 植栽 | E29: 落葉小高木 | F29: 日本を代表する紅葉樹。葉の切れ込みが深く、秋には鮮やかな赤や橙に色づく。 | G29: irohamomiji.jpg | H29: 植栽 イロハモミジ
A30: =IF($B30="","",VLOOKUP($B30,設定!$A$2:$B$13,2,FALSE)&"-"&TEXT(COUNTIF($B$2:$B30,$B30),"00")) | B30: 植栽 | E30: 落葉小高木 | F30: 初夏に白い花を咲かせる落葉樹。側枝の先端に房状に芳香のある直径約25mmほどの花を下向きにつける。 | G30: egonoki.jpg | H30: 植栽 エゴノキ
A31: =IF($B31="","",VLOOKUP($B31,設定!$A$2:$B$13,2,FALSE)&"-"&TEXT(COUNTIF($B$2:$B31,$B31),"00")) | B31: 植栽 | E31: 落葉中高木 | F31: 細い幹と涼しげな葉が特徴の落葉樹。春に白い小花を多数つける。樹形の自然な雰囲気を活かして庭木などに人気。 | G31: aodamo.jpg | H31: 植栽 アオダモ
A32: =IF($B32="","",VLOOKUP($B32,設定!$A$2:$B$13,2,FALSE)&"-"&TEXT(COUNTIF($B$2:$B32,$B32),"00")) | B32: 植栽 | E32: 落葉小木 | F32: バラ科に属する落葉樹。春に白い花を咲かせ、果実が6月に収穫できる。花、果実、紅葉を楽しめる庭木として人気。 | G32: juneberry.jpg | H32: 植栽 ジューンベリー
A33: =IF($B33="","",VLOOKUP($B33,設定!$A$2:$B$13,2,FALSE)&"-"&TEXT(COUNTIF($B$2:$B33,$B33),"00")) | B33: デッキ | C33: 三協アルミ | E33: フロワ | F33: 「内と外」の境界をなくし、すべてのシーンをシームレスに。内と外、自然と建築、人と空間がしなやかに調和します。 | G33: flowa.jpg | H33: アルミデッキ 三協アルミ フロワ | I33: https://alumi.st-grp.co.jp/products/deck/deck/flowa/
A34: =IF($B34="","",VLOOKUP($B34,設定!$A$2:$B$13,2,FALSE)&"-"&TEXT(COUNTIF($B$2:$B34,$B34),"00")) | B34: デッキ | C34: 三協アルミ | E34: ヴィラウッド | F34: 天然木の温もりのある風合いを再現しつつ、耐候性・耐久性に優れ、メンテナンスが容易な人工木デッキ。 | G34: villawood.jpg | H34: 人工木デッキ 三協アルミ ヴィラウッド | I34: https://alumi.st-grp.co.jp/products/deck/villawood_special/?s=story
A35: =IF($B35="","",VLOOKUP($B35,設定!$A$2:$B$13,2,FALSE)&"-"&TEXT(COUNTIF($B$2:$B35,$B35),"00")) | B35: 照明 | C35: LIXIL | E35: 美彩 グランドライト GND-G1型 45° | F35: 地中に埋設してアイポイントとしての使用から、壁面を照射して光のデザインまで楽しめる照明。 | G35: lixilgrandlight.jpg | H35: 12Vライト LIXIL グランドライト GND-G2型 45° 美彩
A36: =IF($B36="","",VLOOKUP($B36,設定!$A$2:$B$13,2,FALSE)&"-"&TEXT(COUNTIF($B$2:$B36,$B36),"00")) | B36: 照明 | C36: LIXIL | E36: 美彩 スパイクスポットライト SSP-G1型 45° | F36: コンパクトでもパワフルな明るさで、シンボルツリーのライトアップに最適な灯り。 | G36: lixilspotlight.jpg | H36: 12Vライト LIXIL スポットライト SP-G2型 45°
A37: =IF($B37="","",VLOOKUP($B37,設定!$A$2:$B$13,2,FALSE)&"-"&TEXT(COUNTIF($B$2:$B37,$B37),"00")) | B37: 照明 | C37: LIXIL | E37: 美彩 ウォールバーライト SWB-L80型/WB-L80型 | F37: バー状のライトでタイルや塗り壁を下から照らして、凹凸の陰影を浮かび上がらせる照明。 | G37: lixilwallbarlight.jpg | H37: LIXIL ウォールバーライト 12V SWB-L80型/WB-L80型 美彩
A38: =IF($B38="","",VLOOKUP($B38,設定!$A$2:$B$13,2,FALSE)&"-"&TEXT(COUNTIF($B$2:$B38,$B38),"00")) | B38: 照明 | C38: LIXIL | E38: 美彩 ローポールライト 丸形/角型 | F38: スリムで美しいデザインが外構に馴染み、夜に煌めくガラスの灯りがアプローチを華やかに演出。 | G38: lixillowpolelight.jpg | H38: ローポールライト 透過型 角型 12V 美彩
A39: =IF($B39="","",VLOOKUP($B39,設定!$A$2:$B$13,2,FALSE)&"-"&TEXT(COUNTIF($B$2:$B39,$B39),"00")) | B39: 照明 | C39: Panasonic | E39: 美ルック 全般拡散 110lmタイプ | F39: ガラス製のカバーで光が優しく拡散。明るさを広げながら、エクステリアのアクセントに。 | G39: panadiffuselight.jpg | H39: 100Vライト パナソニック 美ルック 全般拡散
A40: =IF($B40="","",VLOOKUP($B40,設定!$A$2:$B$13,2,FALSE)&"-"&TEXT(COUNTIF($B$2:$B40,$B40),"00")) | B40: 照明 | C40: Panasonic | E40: 美ルック 上方配光 150lmタイプ | F40: 壁面に美しいスカラップを描き、メリハリのある空間をつくります。植栽のライトアップにも。 | G40: panaindirectlight.jpg | H40: 100Vライト パナソニック 美ルック 上方配光
A41: =IF($B41="","",VLOOKUP($B41,設定!$A$2:$B$13,2,FALSE)&"-"&TEXT(COUNTIF($B$2:$B41,$B41),"00")) | B41: 照明 | C41: Panasonic | E41: 美ルック 下方配光 150lmタイプ | F41: 足元灯として。光源が直接視界に入らないので、まぶしさが軽減されます。 | G41: panadirectlight.jpg | H41: 100Vライト パナソニック 下方拡散 SLW45830 SLW45831
A42: =IF($B42="","",VLOOKUP($B42,設定!$A$2:$B$13,2,FALSE)&"-"&TEXT(COUNTIF($B$2:$B42,$B42),"00")) | B42: 照明 | C42: Panasonic | E42: スポットライト（スパイクタイプ） | F42: スリム＆シンプルで、夜間はもちろん昼間でも存在を主張しないデザイン。 | G42: panaspotlight.jpg | H42: LED パナソニック スポットライト LGW40080 LGW40081 LGW40090 LGW40091 LGW40260 LGW40261
A43: =IF($B43="","",VLOOKUP($B43,設定!$A$2:$B$13,2,FALSE)&"-"&TEXT(COUNTIF($B$2:$B43,$B43),"00")) | B43: 照明 | C43: Panasonic | E43: エントランスライト 遮光タイプ | F43: 遮光版を発光面の頭部に取り付け、歩行者への眩しさに配慮しています。 | G43: panagardenlight.jpg | H43: LED パナソニック ガーデンローポールライト
A44: =IF($B44="","",VLOOKUP($B44,設定!$A$2:$B$13,2,FALSE)&"-"&TEXT(COUNTIF($B$2:$B44,$B44),"00")) | B44: 表札 | C44: 丸三タカギ | E44: アルキア・シャープ | F44: アクセントラインにサインと照明を融合。機能的で繊細な造形が新しいエクステリアシーンを与えます。 | G44: arxiasharp.jpg | H44: 表札 丸三タカギ アルキア・シャープ
A45: =IF($B45="","",VLOOKUP($B45,設定!$A$2:$B$13,2,FALSE)&"-"&TEXT(COUNTIF($B$2:$B45,$B45),"00")) | B45: 表札 | C45: 丸三タカギ | E45: フレイミックス-L | F45: L型スタイルが奥へとさりげなく誘う。様々な空間に融合しやすいシンプルさに、凛とした雰囲気も与えるフレームサイン。 | G45: framixl.jpg | H45: 表札 丸三タカギ フレイミックス-L
A46: =IF($B46="","",VLOOKUP($B46,設定!$A$2:$B$13,2,FALSE)&"-"&TEXT(COUNTIF($B$2:$B46,$B46),"00")) | B46: 表札 | C46: 丸三タカギ | E46: エルカバー | F46: 門壁を引き立てるデザインパーツとしても機能するL型インターホンカバー。豊富な開口パターンで大型子機にも対応可能。 | G46: elcover.jpg | H46: 表札 丸三タカギ エルカバー
... A55: =IF($B55="","",VLOOKUP($B55,設定!$A$2:$B$13,2,FALSE)&"-"&TEXT(COUNTIF($B$2:$B55,$B55),"00")) | B55: 表札 | C55: 丸三タカギ | E55: ビットレター | F55: 立体的に仕上げたバータイプデザイン。シンプルながらも静かな存在感を放ちます。 | G55: bitletter.jpg | H55: 表札 丸三タカギ ビットレター
A56: =IF($B56="","",VLOOKUP($B56,設定!$A$2:$B$13,2,FALSE)&"-"&TEXT(COUNTIF($B$2:$B56,$B56),"00")) | B56: ポスト | C56: オンリーワン | D56: 蓋つきポスト | E56: パーサス プレーン | F56: 価格を抑えながら、デザインと機能は進化。ダイヤル錠を見せないスッキリ美しいデザイン。 | G56: pursusplain.jpg | H56: 蓋つきポスト オンリーワン パーサス プレーン
A57: =IF($B57="","",VLOOKUP($B57,設定!$A$2:$B$13,2,FALSE)&"-"&TEXT(COUNTIF($B$2:$B57,$B57),"00")) | B57: ポスト | C57: ディーズガーデン | D57: 蓋つきポスト | E57: アンジュ | F57: アンティークな陶器の質感で、可愛いらしいレリーフをデザイン。ナチュラルな優しくフランス雑貨を想わせます。 | G57: ange.jpg | H57: 蓋つきポスト ディーズガーデン アンジュ
A58: =IF($B58="","",VLOOKUP($B58,設定!$A$2:$B$13,2,FALSE)&"-"&TEXT(COUNTIF($B$2:$B58,$B58),"00")) | B58: ポスト | C58: ディーズガーデン | D58: 口金ポスト | E58: アンジュ-F | F58: 壁面埋め込み型の口金ポスト。フランス雑貨をイメージしたアンティークなテラコッタ風デザイン。 | G58: angef.jpg | H58: 口金ポスト ディーズガーデン アンジュ-F
A59: =IF($B59="","",VLOOKUP($B59,設定!$A$2:$B$13,2,FALSE)&"-"&TEXT(COUNTIF($B$2:$B59,$B59),"00")) | B59: ポスト | C59: LIXIL | D59: 口金ポスト | E59: エクスポスト | F59: ボックスは容量に合わせて選べる4タイプ。口金部分が露出した壁埋め込み仕様のポストです。 | G59: expost.jpg | H59: 口金ポスト LIXIL エクスポスト 口金タイプ
A60: =IF($B60="","",VLOOKUP($B60,設定!$A$2:$B$13,2,FALSE)&"-"&TEXT(COUNTIF($B$2:$B60,$B60),"00")) | B60: ポスト | C60: オンリーワン | D60: 独立ポスト | E60: フィールⅡ | F60: どこか懐かしさを感じる佇まいに、洗練されたフォルムが融合。エントランスをお洒落に演出します。 | G60: feelⅡ.jpg | H60: 独立ポスト オンリーワン フィールII
A61: =IF($B61="","",VLOOKUP($B61,設定!$A$2:$B$13,2,FALSE)&"-"&TEXT(COUNTIF($B$2:$B61,$B61),"00")) | B61: ポスト | C61: ギャザー/EXISLAND | D61: 独立ポスト | E61: ボビ | F61: フィンランド生まれの郵便ポスト。個性豊かな12色が魅力。 | G61: bobi.jpg | H61: 独立ポスト ギャザー ボビ
...

Sheet カラー展開
A1: 商品ID* | B1: 商品名（参考） | C1: 表示順 | D1: カラー名 | E1: カラーコード（HEX）
A2: floor-01 | B2: =IFERROR(VLOOKUP($A2,商品マスタ!$A:$E,5,FALSE),"") | C2: 1 | D2: クロムグレー | E2: #b6a99a
A3: floor-01 | B3: =IFERROR(VLOOKUP($A3,商品マスタ!$A:$E,5,FALSE),"") | C3: 2 | D3: ウォームグレー | E3: #c4b7af
A4: floor-01 | B4: =IFERROR(VLOOKUP($A4,商品マスタ!$A:$E,5,FALSE),"") | C4: 3 | D4: ダークグレー | E4: #4b504e
A5: floor-01 | B5: =IFERROR(VLOOKUP($A5,商品マスタ!$A:$E,5,FALSE),"") | C5: 4 | D5: アースベージュ | E5: #c6b89e
A6: floor-01 | B6: =IFERROR(VLOOKUP($A6,商品マスタ!$A:$E,5,FALSE),"") | C6: 5 | D6: ナチュラルブラウン | E6: #9f8377
A7: floor-01 | B7: =IFERROR(VLOOKUP($A7,商品マスタ!$A:$E,5,FALSE),"") | C7: 6 | D7: ロッソブラウン | E7: #6e5955
A8: floor-02 | B8: =IFERROR(VLOOKUP($A8,商品マスタ!$A:$E,5,FALSE),"") | C8: 1 | D8: ポルドブラウン | E8: #aa8d7d
A9: floor-02 | B9: =IFERROR(VLOOKUP($A9,商品マスタ!$A:$E,5,FALSE),"") | C9: 2 | D9: ポルドベージュ | E9: #8f7868
A10: floor-02 | B10: =IFERROR(VLOOKUP($A10,商品マスタ!$A:$E,5,FALSE),"") | C10: 3 | D10: ポルドイエロー | E10: #c4ae96
A11: floor-02 | B11: =IFERROR(VLOOKUP($A11,商品マスタ!$A:$E,5,FALSE),"") | C11: 4 | D11: ポルドガーネット | E11: #8e7571
A12: floor-02 | B12: =IFERROR(VLOOKUP($A12,商品マスタ!$A:$E,5,FALSE),"") | C12: 5 | D12: ポルドグレー | E12: #87827f
A13: floor-02 | B13: =IFERROR(VLOOKUP($A13,商品マスタ!$A:$E,5,FALSE),"") | C13: 6 | D13: ポルドダーク | E13: #6f696b
... A251: water-06 | B251: =IFERROR(VLOOKUP($A251,商品マスタ!$A:$E,5,FALSE),"") | C251: 1 | D251: ステンレス | E251: #dddada
A252: ▼ ここから新規追加 ▼
B253: =IFERROR(VLOOKUP($A253,商品マスタ!$A:$E,5,FALSE),"")
B254: =IFERROR(VLOOKUP($A254,商品マスタ!$A:$E,5,FALSE),"")
B255: =IFERROR(VLOOKUP($A255,商品マスタ!$A:$E,5,FALSE),"")
B256: =IFERROR(VLOOKUP($A256,商品マスタ!$A:$E,5,FALSE),"")
B257: =IFERROR(VLOOKUP($A257,商品マスタ!$A:$E,5,FALSE),"")
B258: =IFERROR(VLOOKUP($A258,商品マスタ!$A:$E,5,FALSE),"")
B259: =IFERROR(VLOOKUP($A259,商品マスタ!$A:$E,5,FALSE),"")
B260: =IFERROR(VLOOKUP($A260,商品マスタ!$A:$E,5,FALSE),"")
B261: =IFERROR(VLOOKUP($A261,商品マスタ!$A:$E,5,FALSE),"")
B262: =IFERROR(VLOOKUP($A262,商品マスタ!$A:$E,5,FALSE),"")
B263: =IFERROR(VLOOKUP($A263,商品マスタ!$A:$E,5,FALSE),"")
B264: =IFERROR(VLOOKUP($A264,商品マスタ!$A:$E,5,FALSE),"")
... B282: =IFERROR(VLOOKUP($A282,商品マスタ!$A:$E,5,FALSE),"")

Sheet カタログリンク
A1: 商品ID（自動） | B1: 商品名（参考） | C1: リンク1 表示文言 | D1: リンク1 URL | E1: リンク2 表示文言 | F1: リンク2 URL
A2: ='商品マスタ'!A2 | B2: ='商品マスタ'!E2 | C2: カタログを見る【関東】 | D2: https://toyo-kogyo.icata.net/iportal/cv.do?c=24053650000&pg=93&v=TYK10002&d=TOYOD01 | E2: カタログを見る【九州】 | F2: https://toyo-kogyo.icata.net/iportal/cv.do?c=24053640000&pg=93&v=TYK10002&d=TOYOD01
A3: ='商品マスタ'!A3 | B3: ='商品マスタ'!E3 | C3: カタログを見る【関東】 | D3: https://toyo-kogyo.icata.net/iportal/cv.do?c=24053650000&pg=106&v=TYK10002&d=TOYOD01 | E3: カタログを見る【九州】 | F3: https://toyo-kogyo.icata.net/iportal/cv.do?c=24053640000&pg=106&v=TYK10002&d=TOYOD01
A4: ='商品マスタ'!A4 | B4: ='商品マスタ'!E4 | C4: カタログを見る【関東】 | D4: https://toyo-kogyo.icata.net/iportal/cv.do?c=24053650000&pg=124&v=TYK10002&d=TOYOD01 | E4: カタログを見る【九州】 | F4: https://toyo-kogyo.icata.net/iportal/cv.do?c=24053640000&pg=124&v=TYK10002&d=TOYOD01
A5: ='商品マスタ'!A5 | B5: ='商品マスタ'!E5 | C5: カタログを見る【関東】 | D5: https://toyo-kogyo.icata.net/iportal/cv.do?c=24053650000&pg=105&v=TYK10002&d=TOYOD01 | E5: カタログを見る【九州】 | F5: https://toyo-kogyo.icata.net/iportal/cv.do?c=24053640000&pg=105&v=TYK10002&d=TOYOD01
A6: ='商品マスタ'!A6 | B6: ='商品マスタ'!E6 | C6: カタログを見る【関東】 | D6: https://toyo-kogyo.icata.net/iportal/cv.do?c=24053650000&pg=146&v=TYK10002&d=TOYOD01 | E6: カタログを見る【九州】 | F6: https://toyo-kogyo.icata.net/iportal/cv.do?c=24053640000&pg=146&v=TYK10002&d=TOYOD01
A7: ='商品マスタ'!A7 | B7: ='商品マスタ'!E7 | C7: カタログを見る【関東】 | D7: https://toyo-kogyo.icata.net/iportal/cv.do?c=24053650000&pg=126&v=TYK10002&d=TOYOD01 | E7: カタログを見る【九州】 | F7: https://toyo-kogyo.icata.net/iportal/cv.do?c=24053640000&pg=126&v=TYK10002&d=TOYOD01
A8: ='商品マスタ'!A8 | B8: ='商品マスタ'!E8 | C8: カタログを見る【関東】 | D8: https://dmp-net.meclib.jp/library/books/catalog2025/book/index.html#target/page_no=281
A9: ='商品マスタ'!A9 | B9: ='商品マスタ'!E9 | C9: カタログを見る【九州】 | D9: https://saas.actibookone.com/content/detail?param=eyJjb250ZW50TnVtIjoxNzY2NDd9&detailFlg=0&pNo=156
A10: ='商品マスタ'!A10 | B10: ='商品マスタ'!E10 | C10: カタログを見る【関東】 | D10: https://dmp-net.meclib.jp/library/books/catalog2025/book/index.html#target/page_no=283
A11: ='商品マスタ'!A11 | B11: ='商品マスタ'!E11 | C11: カタログを見る【九州】 | D11: https://saas.actibookone.com/content/detail?param=eyJjb250ZW50TnVtIjoxNzY2NDd9&detailFlg=0&pNo=144
A12: ='商品マスタ'!A12 | B12: ='商品マスタ'!E12 | C12: カタログを見る【関東】 | D12: https://toyo-kogyo.icata.net/iportal/cv.do?c=24053650000&pg=133&v=TYK10002&d=TOYOD01 | E12: カタログを見る【九州】 | F12: https://toyo-kogyo.icata.net/iportal/cv.do?c=24053640000&pg=133&v=TYK10002&d=TOYOD01
A13: ='商品マスタ'!A13 | B13: ='商品マスタ'!E13 | C13: カタログを見る【関東】 | D13: https://dmp-net.meclib.jp/library/books/catalog2025/book/index.html#target/page_no=108 | E13: カタログを見る【九州】 | F13: https://exis.icata.net/iportal/cv.do?c=1975150000&pg=52&v=EXS00001&d=EXIS01
A14: ='商品マスタ'!A14 | B14: ='商品マスタ'!E14 | C14: カタログを見る【関東】 | D14: https://toyo-kogyo.icata.net/iportal/cv.do?c=24053650000&pg=66&v=TYK10002&d=TOYOD01 | E14: カタログを見る【九州】 | F14: https://toyo-kogyo.icata.net/iportal/cv.do?c=24053640000&pg=66&v=TYK10002&d=TOYOD01
A15: ='商品マスタ'!A15 | B15: ='商品マスタ'!E15 | C15: カタログを見る【関東】 | D15: https://dmp-net.meclib.jp/library/books/catalog2025/book/index.html#target/page_no=73 | E15: カタログを見る【九州】 | F15: https://exis.icata.net/iportal/cv.do?c=1975150000&pg=41&v=EXS00001&d=EXIS01
A16: ='商品マスタ'!A16 | B16: ='商品マスタ'!E16 | C16: カタログを見る【関東】 | D16: https://dmp-net.meclib.jp/library/books/catalog2025/book/index.html#target/page_no=84
A17: ='商品マスタ'!A17 | B17: ='商品マスタ'!E17 | C17: カタログを見る【九州】 | D17: https://exis.icata.net/iportal/cv.do?c=1975150000&pg=33&v=EXS00001&d=EXIS01
A18: ='商品マスタ'!A18 | B18: ='商品マスタ'!E18 | C18: カタログを見る【関東】 | D18: https://dmp-net.meclib.jp/library/books/catalog2025/book/index.html#target/page_no=75 | E18: カタログを見る【九州】 | F18: https://exis.icata.net/iportal/cv.do?c=1975150000&pg=28&v=EXS00001&d=EXIS01
A19: ='商品マスタ'!A19 | B19: ='商品マスタ'!E19 | C19: カタログを見る【関東】 | D19: https://dmp-net.meclib.jp/library/books/catalog2025/book/index.html#target/page_no=76 | E19: カタログを見る【九州】 | F19: https://exis.icata.net/iportal/cv.do?c=1975150000&pg=38&v=EXS00001&d=EXIS01
A20: ='商品マスタ'!A20 | B20: ='商品マスタ'!E20 | C20: カタログを見る | D20: https://www.ic-ryowa.com/webcatalog/?pNo=118
A21: ='商品マスタ'!A21 | B21: ='商品マスタ'!E21 | C21: カタログを見る | D21: https://www.ic-ryowa.com/webcatalog/?pNo=46
A22: ='商品マスタ'!A22 | B22: ='商品マスタ'!E22 | C22: カタログを見る | D22: https://www.ic-ryowa.com/webcatalog/?pNo=52
A23: ='商品マスタ'!A23 | B23: ='商品マスタ'!E23 | C23: カタログを見る | D23: https://www.catalabo.org/iportal/cv.do?c=86663320000&pg=149&v=CATALABO&d=link
A24: ='商品マスタ'!A24 | B24: ='商品マスタ'!E24 | C24: カタログを見る【関東】 | D24: https://toyo-kogyo.icata.net/iportal/CatalogViewInterfaceStartUpAction.do?method=startUp&mode=PAGE&volumeID=TYK10002&catalogId=24053650000&pageGroupId=95&designID=TOYOD01&catalogCategoryId= | E24: カタログを見る【九州】 | F24: https://toyo-kogyo.icata.net/iportal/CatalogViewInterfaceStartUpAction.do?method=startUp&mode=PAGE&volumeID=TYK10002&catalogId=24053640000&pageGroupId=95&designID=TOYOD01&catalogCategoryId=
A25: ='商品マスタ'!A25 | B25: ='商品マスタ'!E25 | C25: カタログを見る【関東】 | D25: https://toyo-kogyo.icata.net/iportal/CatalogViewInterfaceStartUpAction.do?method=startUp&mode=PAGE&volumeID=TYK10002&catalogId=24053650000&pageGroupId=148&designID=TOYOD01&catalogCategoryId= | E25: カタログを見る【九州】 | F25: https://toyo-kogyo.icata.net/iportal/CatalogViewInterfaceStartUpAction.do?method=startUp&mode=PAGE&volumeID=TYK10002&catalogId=24053640000&pageGroupId=148&designID=TOYOD01&catalogCategoryId=
A26: ='商品マスタ'!A26 | B26: ='商品マスタ'!E26 | C26: カタログを見る【関東】 | D26: https://toyo-kogyo.icata.net/iportal/CatalogViewInterfaceStartUpAction.do?method=startUp&mode=PAGE&volumeID=TYK10002&catalogId=24053650000&pageGroupId=116&designID=TOYOD01&catalogCategoryId= | E26: カタログを見る【九州】 | F26: https://toyo-kogyo.icata.net/iportal/CatalogViewInterfaceStartUpAction.do?method=startUp&mode=PAGE&volumeID=TYK10002&catalogId=24053640000&pageGroupId=116&designID=TOYOD01&catalogCategoryId=
A27: ='商品マスタ'!A27 | B27: ='商品マスタ'!E27 | C27: おすすめカラーはこちら | D27: jolipate_color.html
A28: ='商品マスタ'!A28 | B28: ='商品マスタ'!E28 | C28: Wikipediaを見る | D28: https://ja.wikipedia.org/wiki/%E3%82%A4%E3%83%AD%E3%83%8F%E3%83%A2%E3%83%9F%E3%82%B8#.E3.83.A4.E3.83.9E.E3.83.A2.E3.83.9F.E3.82.B8
A29: ='商品マスタ'!A29 | B29: ='商品マスタ'!E29 | C29: Wikipediaを見る | D29: https://ja.wikipedia.org/wiki/%E3%82%A4%E3%83%AD%E3%83%8F%E3%83%A2%E3%83%9F%E3%82%B8
A30: ='商品マスタ'!A30 | B30: ='商品マスタ'!E30 | C30: Wikipediaを見る | D30: https://ja.wikipedia.org/wiki/%E3%82%A8%E3%82%B4%E3%83%8E%E3%82%AD
A31: ='商品マスタ'!A31 | B31: ='商品マスタ'!E31 | C31: Wikipediaを見る | D31: https://ja.wikipedia.org/wiki/%E3%82%A2%E3%82%AA%E3%83%80%E3%83%A2
A32: ='商品マスタ'!A32 | B32: ='商品マスタ'!E32 | C32: Wikipediaを見る | D32: https://ja.wikipedia.org/wiki/%E3%82%B8%E3%83%A5%E3%83%BC%E3%83%B3%E3%83%99%E3%83%AA%E3%83%BC
A33: ='商品マスタ'!A33 | B33: ='商品マスタ'!E33 | C33: カタログを見る | D33: https://appsp.st-grp.co.jp/iportal/CatalogViewInterfaceStartUpAction.do?method=startUp&mode=PAGE&volumeID=STAWC001&catalogId=20765880000&pageGroupId=34&designID=WCAT001&catalogCategoryId=
A34: ='商品マスタ'!A34 | B34: ='商品マスタ'!E34 | C34: カタログを見る | D34: https://appsp.st-grp.co.jp/iportal/CatalogViewInterfaceStartUpAction.do?method=startUp&mode=PAGE&volumeID=STAWC001&catalogId=20765880000&pageGroupId=67&designID=WCAT001&catalogCategoryId=
A35: ='商品マスタ'!A35 | B35: ='商品マスタ'!E35 | C35: カタログを見る | D35: https://webcatalog.lixil.co.jp/cgi-bin/openCatalogAuth.cgi?c=EV1200&p=98
A36: ='商品マスタ'!A36 | B36: ='商品マスタ'!E36 | C36: カタログを見る | D36: https://webcatalog.lixil.co.jp/cgi-bin/openCatalogAuth.cgi?c=EV1200&p=90
A37: ='商品マスタ'!A37 | B37: ='商品マスタ'!E37 | C37: カタログを見る | D37: https://webcatalog.lixil.co.jp/cgi-bin/openCatalogAuth.cgi?c=EV1200&p=94
A38: ='商品マスタ'!A38 | B38: ='商品マスタ'!E38 | C38: カタログを見る | D38: https://webcatalog.lixil.co.jp/cgi-bin/openCatalogAuth.cgi?c=EV1200&p=125
... A60: ='商品マスタ'!A60 | B60: ='商品マスタ'!E60 | C60: カタログを見る | D60: https://onlyoneclub.icata.net/iportal/cv.do?c=3317760000&pg=164&v=OOC00001&d=OOC01
A61: ='商品マスタ'!A61 | B61: ='商品マスタ'!E61 | C61: カタログを見る【関東】 | D61: https://dmp-net.meclib.jp/library/books/gather_vol15_meiku/book/index.html#target/page_no=122 | E61: カタログを見る【九州】 | F61: https://exis.icata.net/iportal/cv.do?c=1975150000&pg=210&v=EXS00001&d=EXIS01
...

Sheet 設定
A1: 掲載カテゴリー | B1: コード
A2: 床材 | B2: floor
A3: 壁材 | B3: wall
A4: 植栽 | B4: plants
A5: デッキ | B5: deck
A6: 照明 | B6: light
A7: 表札 | B7: sign
A8: ポスト | B8: post
A9: 機能門柱 | B9: gatepost
A10: 人工芝・砂利 | B10: grass
A11: 立水栓 | B11: water
A12: 木製エクステリア（Gストック） | B12: gstok
A13: デザインフェンス | B13: fence
